2023-03-14 07:31:05,812 ERROR: Exception on /login [GET] [in /home/pi/Desktop/math_website/venv/lib/python3.7/site-packages/flask/app.py:1742]
Traceback (most recent call last):
  File "/home/pi/Desktop/math_website/venv/lib/python3.7/site-packages/flask/app.py", line 2525, in wsgi_app
    response = self.full_dispatch_request()
  File "/home/pi/Desktop/math_website/venv/lib/python3.7/site-packages/flask/app.py", line 1822, in full_dispatch_request
    rv = self.handle_user_exception(e)
  File "/home/pi/Desktop/math_website/venv/lib/python3.7/site-packages/flask/app.py", line 1820, in full_dispatch_request
    rv = self.dispatch_request()
  File "/home/pi/Desktop/math_website/venv/lib/python3.7/site-packages/flask/app.py", line 1796, in dispatch_request
    return self.ensure_sync(self.view_functions[rule.endpoint])(**view_args)
  File "/home/pi/Desktop/math_website/app/routes.py", line 136, in login
    return render_template('login.html', title='MassiveDiscipline', form=form)
  File "/home/pi/Desktop/math_website/venv/lib/python3.7/site-packages/flask/templating.py", line 147, in render_template
    return _render(app, template, context)
  File "/home/pi/Desktop/math_website/venv/lib/python3.7/site-packages/flask/templating.py", line 130, in _render
    rv = template.render(context)
  File "/home/pi/Desktop/math_website/venv/lib/python3.7/site-packages/jinja2/environment.py", line 1301, in render
    self.environment.handle_exception()
  File "/home/pi/Desktop/math_website/venv/lib/python3.7/site-packages/jinja2/environment.py", line 936, in handle_exception
    raise rewrite_traceback_stack(source=source)
  File "/home/pi/Desktop/math_website/app/templates/login.html", line 2, in top-level template code
    {% import 'bootstrap/wtf.html' as wtf %}
  File "/home/pi/Desktop/math_website/app/templates/base.html", line 1, in top-level template code
    {% extends 'bootstrap/base.html' %}
  File "/home/pi/Desktop/math_website/venv/lib/python3.7/site-packages/flask_bootstrap/templates/bootstrap/base.html", line 1, in top-level template code
    {% block doc -%}
  File "/home/pi/Desktop/math_website/venv/lib/python3.7/site-packages/flask_bootstrap/templates/bootstrap/base.html", line 4, in block 'doc'
    {%- block html %}
  File "/home/pi/Desktop/math_website/venv/lib/python3.7/site-packages/flask_bootstrap/templates/bootstrap/base.html", line 20, in block 'html'
    {% block body -%}
  File "/home/pi/Desktop/math_website/venv/lib/python3.7/site-packages/flask_bootstrap/templates/bootstrap/base.html", line 23, in block 'body'
    {% block content -%}
  File "/home/pi/Desktop/math_website/app/templates/base.html", line 49, in block 'content'
    {% block app_content %}{% endblock %}
  File "/home/pi/Desktop/math_website/app/templates/login.html", line 12, in block 'app_content'
    <p>{{ ('New User?') }} <a href="{{ url_for('auth.register') }}">{{ ('Click to Register!') }}</a></p>
  File "/home/pi/Desktop/math_website/venv/lib/python3.7/site-packages/flask/app.py", line 2031, in url_for
    return self.handle_url_build_error(error, endpoint, values)
  File "/home/pi/Desktop/math_website/venv/lib/python3.7/site-packages/flask/app.py", line 2025, in url_for
    force_external=_external,
  File "/home/pi/Desktop/math_website/venv/lib/python3.7/site-packages/werkzeug/routing/map.py", line 917, in build
    raise BuildError(endpoint, values, method, self)
werkzeug.routing.exceptions.BuildError: Could not build url for endpoint 'auth.register'. Did you mean 'register' instead?
2023-03-14 07:32:00,369 INFO: Math Website startup [in /home/pi/Desktop/math_website/app/__init__.py:62]
2023-03-14 07:36:59,796 INFO: Math Website startup [in /home/pi/Desktop/math_website/app/__init__.py:62]
2023-03-14 07:54:44,238 INFO: Math Website startup [in /home/pi/Desktop/math_website/app/__init__.py:62]
2023-03-14 07:56:23,258 INFO: Math Website startup [in /home/pi/Desktop/math_website/app/__init__.py:62]
2023-03-14 07:57:18,084 INFO: Math Website startup [in /home/pi/Desktop/math_website/app/__init__.py:62]
2023-03-14 07:59:35,003 INFO: Math Website startup [in /home/pi/Desktop/math_website/app/__init__.py:62]
2023-03-15 15:46:00,332 INFO: Math Website startup [in /home/pi/Desktop/math_website/app/__init__.py:62]
2023-03-15 15:46:50,604 INFO: Math Website startup [in /home/pi/Desktop/math_website/app/__init__.py:62]
2023-03-15 15:51:58,223 INFO: Math Website startup [in /home/pi/Desktop/math_website/app/__init__.py:62]
2023-03-15 15:52:21,889 ERROR: Exception on / [GET] [in /home/pi/Desktop/math_website/venv/lib/python3.7/site-packages/flask/app.py:1742]
Traceback (most recent call last):
  File "/home/pi/Desktop/math_website/venv/lib/python3.7/site-packages/flask/app.py", line 2525, in wsgi_app
    response = self.full_dispatch_request()
  File "/home/pi/Desktop/math_website/venv/lib/python3.7/site-packages/flask/app.py", line 1822, in full_dispatch_request
    rv = self.handle_user_exception(e)
  File "/home/pi/Desktop/math_website/venv/lib/python3.7/site-packages/flask/app.py", line 1820, in full_dispatch_request
    rv = self.dispatch_request()
  File "/home/pi/Desktop/math_website/venv/lib/python3.7/site-packages/flask/app.py", line 1796, in dispatch_request
    return self.ensure_sync(self.view_functions[rule.endpoint])(**view_args)
  File "/home/pi/Desktop/math_website/venv/lib/python3.7/site-packages/flask_login/utils.py", line 290, in decorated_view
    return current_app.ensure_sync(func)(*args, **kwargs)
  File "/home/pi/Desktop/math_website/app/routes.py", line 236, in index
    form = form, posts=posts.items, next_url=next_url, prev_url=prev_url)
  File "/home/pi/Desktop/math_website/venv/lib/python3.7/site-packages/flask/templating.py", line 147, in render_template
    return _render(app, template, context)
  File "/home/pi/Desktop/math_website/venv/lib/python3.7/site-packages/flask/templating.py", line 130, in _render
    rv = template.render(context)
  File "/home/pi/Desktop/math_website/venv/lib/python3.7/site-packages/jinja2/environment.py", line 1301, in render
    self.environment.handle_exception()
  File "/home/pi/Desktop/math_website/venv/lib/python3.7/site-packages/jinja2/environment.py", line 936, in handle_exception
    raise rewrite_traceback_stack(source=source)
  File "/home/pi/Desktop/math_website/app/templates/index.html", line 3, in top-level template code
    {% import 'bootstrap/wtf.html' as wtf %}
  File "/home/pi/Desktop/math_website/app/templates/base.html", line 1, in top-level template code
    {% extends 'bootstrap/base.html' %}
  File "/home/pi/Desktop/math_website/venv/lib/python3.7/site-packages/flask_bootstrap/templates/bootstrap/base.html", line 1, in top-level template code
    {% block doc -%}
  File "/home/pi/Desktop/math_website/venv/lib/python3.7/site-packages/flask_bootstrap/templates/bootstrap/base.html", line 4, in block 'doc'
    {%- block html %}
  File "/home/pi/Desktop/math_website/venv/lib/python3.7/site-packages/flask_bootstrap/templates/bootstrap/base.html", line 20, in block 'html'
    {% block body -%}
  File "/home/pi/Desktop/math_website/venv/lib/python3.7/site-packages/flask_bootstrap/templates/bootstrap/base.html", line 23, in block 'body'
    {% block content -%}
  File "/home/pi/Desktop/math_website/app/templates/base.html", line 125, in block 'content'
    {% block app_content %}{% endblock %}
  File "/home/pi/Desktop/math_website/app/templates/index.html", line 6, in block 'app_content'
    <h1>{{ _('Hi, %(username)s!', username=current_user.username) }}</h1>
  File "/home/pi/Desktop/math_website/venv/lib/python3.7/site-packages/jinja2/utils.py", line 83, in from_obj
    if hasattr(obj, "jinja_pass_arg"):
jinja2.exceptions.UndefinedError: '_' is undefined
2023-03-15 15:52:50,159 INFO: Math Website startup [in /home/pi/Desktop/math_website/app/__init__.py:62]
