2023-04-27 08:06:27,386 ERROR: Exception on / [GET] [in /home/pi/Desktop/math_website/venv/lib/python3.7/site-packages/flask/app.py:1742]
Traceback (most recent call last):
  File "/home/pi/Desktop/math_website/venv/lib/python3.7/site-packages/flask/app.py", line 2525, in wsgi_app
    response = self.full_dispatch_request()
  File "/home/pi/Desktop/math_website/venv/lib/python3.7/site-packages/flask/app.py", line 1822, in full_dispatch_request
    rv = self.handle_user_exception(e)
  File "/home/pi/Desktop/math_website/venv/lib/python3.7/site-packages/flask/app.py", line 1820, in full_dispatch_request
    rv = self.dispatch_request()
  File "/home/pi/Desktop/math_website/venv/lib/python3.7/site-packages/flask/app.py", line 1796, in dispatch_request
    return self.ensure_sync(self.view_functions[rule.endpoint])(**view_args)
  File "/home/pi/Desktop/math_website/venv/lib/python3.7/site-packages/flask_login/utils.py", line 290, in decorated_view
    return current_app.ensure_sync(func)(*args, **kwargs)
  File "/home/pi/Desktop/math_website/app/main/routes.py", line 105, in index
    form = form, posts=posts.items, next_url=next_url, prev_url=prev_url)
  File "/home/pi/Desktop/math_website/venv/lib/python3.7/site-packages/flask/templating.py", line 147, in render_template
    return _render(app, template, context)
  File "/home/pi/Desktop/math_website/venv/lib/python3.7/site-packages/flask/templating.py", line 130, in _render
    rv = template.render(context)
  File "/home/pi/Desktop/math_website/venv/lib/python3.7/site-packages/jinja2/environment.py", line 1301, in render
    self.environment.handle_exception()
  File "/home/pi/Desktop/math_website/venv/lib/python3.7/site-packages/jinja2/environment.py", line 936, in handle_exception
    raise rewrite_traceback_stack(source=source)
  File "/home/pi/Desktop/math_website/app/templates/index.html", line 3, in top-level template code
    {% import 'bootstrap/wtf.html' as wtf %}
  File "/home/pi/Desktop/math_website/app/templates/base.html", line 1, in top-level template code
    {% extends 'bootstrap/base.html' %}
  File "/home/pi/Desktop/math_website/venv/lib/python3.7/site-packages/flask_bootstrap/templates/bootstrap/base.html", line 1, in top-level template code
    {% block doc -%}
  File "/home/pi/Desktop/math_website/venv/lib/python3.7/site-packages/flask_bootstrap/templates/bootstrap/base.html", line 4, in block 'doc'
    {%- block html %}
  File "/home/pi/Desktop/math_website/venv/lib/python3.7/site-packages/flask_bootstrap/templates/bootstrap/base.html", line 20, in block 'html'
    {% block body -%}
  File "/home/pi/Desktop/math_website/venv/lib/python3.7/site-packages/flask_bootstrap/templates/bootstrap/base.html", line 23, in block 'body'
    {% block content -%}
  File "/home/pi/Desktop/math_website/app/templates/base.html", line 74, in block 'content'
    {% block app_content %}{% endblock %}
  File "/home/pi/Desktop/math_website/app/templates/index.html", line 105, in block 'app_content'
    url_for("man.general_exponential_transform")
  File "/home/pi/Desktop/math_website/venv/lib/python3.7/site-packages/flask/app.py", line 2031, in url_for
    return self.handle_url_build_error(error, endpoint, values)
  File "/home/pi/Desktop/math_website/venv/lib/python3.7/site-packages/flask/app.py", line 2025, in url_for
    force_external=_external,
  File "/home/pi/Desktop/math_website/venv/lib/python3.7/site-packages/werkzeug/routing/map.py", line 917, in build
    raise BuildError(endpoint, values, method, self)
werkzeug.routing.exceptions.BuildError: Could not build url for endpoint 'man.general_exponential_transform'. Did you mean 'main.general_exponential_transform' instead?
2023-04-27 08:07:27,834 INFO: Math Website startup [in /home/pi/Desktop/math_website/app/__init__.py:78]
2023-04-27 08:20:00,728 INFO: Math Website startup [in /home/pi/Desktop/math_website/app/__init__.py:78]
2023-04-29 08:08:38,763 INFO: Math Website startup [in /home/pi/Desktop/math_website/app/__init__.py:78]
2023-04-29 08:08:48,063 INFO: Math Website startup [in /home/pi/Desktop/math_website/app/__init__.py:78]
2023-04-29 08:56:41,178 INFO: Math Website startup [in /home/pi/Desktop/math_website/app/__init__.py:94]
2023-04-29 09:00:09,487 INFO: Math Website startup [in /home/pi/Desktop/math_website/app/__init__.py:94]
2023-04-29 09:02:09,024 INFO: Math Website startup [in /home/pi/Desktop/math_website/app/__init__.py:94]
2023-04-29 09:04:58,661 INFO: Math Website startup [in /home/pi/Desktop/math_website/app/__init__.py:94]
2023-04-29 09:10:25,867 INFO: Math Website startup [in /home/pi/Desktop/math_website/app/__init__.py:94]
2023-04-29 09:11:01,857 ERROR: Exception on /auth/reset_password_request [POST] [in /home/pi/Desktop/math_website/venv/lib/python3.7/site-packages/flask/app.py:1742]
Traceback (most recent call last):
  File "/home/pi/Desktop/math_website/venv/lib/python3.7/site-packages/flask/app.py", line 2525, in wsgi_app
    response = self.full_dispatch_request()
  File "/home/pi/Desktop/math_website/venv/lib/python3.7/site-packages/flask/app.py", line 1822, in full_dispatch_request
    rv = self.handle_user_exception(e)
  File "/home/pi/Desktop/math_website/venv/lib/python3.7/site-packages/flask/app.py", line 1820, in full_dispatch_request
    rv = self.dispatch_request()
  File "/home/pi/Desktop/math_website/venv/lib/python3.7/site-packages/flask/app.py", line 1796, in dispatch_request
    return self.ensure_sync(self.view_functions[rule.endpoint])(**view_args)
  File "/home/pi/Desktop/math_website/app/auth/routes.py", line 190, in reset_password_request
    send_password_reset_email(user)
  File "/home/pi/Desktop/math_website/app/auth/email.py", line 20, in send_password_reset_email
    user=user, token=token)
  File "/home/pi/Desktop/math_website/app/email.py", line 33, in send_email
    msg.body = text_body
NameError: name 'msg' is not defined
2023-04-29 09:11:17,242 ERROR: Exception on /auth/reset_password_request [POST] [in /home/pi/Desktop/math_website/venv/lib/python3.7/site-packages/flask/app.py:1742]
Traceback (most recent call last):
  File "/home/pi/Desktop/math_website/venv/lib/python3.7/site-packages/flask/app.py", line 2525, in wsgi_app
    response = self.full_dispatch_request()
  File "/home/pi/Desktop/math_website/venv/lib/python3.7/site-packages/flask/app.py", line 1822, in full_dispatch_request
    rv = self.handle_user_exception(e)
  File "/home/pi/Desktop/math_website/venv/lib/python3.7/site-packages/flask/app.py", line 1820, in full_dispatch_request
    rv = self.dispatch_request()
  File "/home/pi/Desktop/math_website/venv/lib/python3.7/site-packages/flask/app.py", line 1796, in dispatch_request
    return self.ensure_sync(self.view_functions[rule.endpoint])(**view_args)
  File "/home/pi/Desktop/math_website/app/auth/routes.py", line 190, in reset_password_request
    send_password_reset_email(user)
  File "/home/pi/Desktop/math_website/app/auth/email.py", line 20, in send_password_reset_email
    user=user, token=token)
  File "/home/pi/Desktop/math_website/app/email.py", line 33, in send_email
    msg.body = text_body
NameError: name 'msg' is not defined
2023-04-29 09:11:31,239 ERROR: Exception on /auth/reset_password_request [POST] [in /home/pi/Desktop/math_website/venv/lib/python3.7/site-packages/flask/app.py:1742]
Traceback (most recent call last):
  File "/home/pi/Desktop/math_website/venv/lib/python3.7/site-packages/flask/app.py", line 2525, in wsgi_app
    response = self.full_dispatch_request()
  File "/home/pi/Desktop/math_website/venv/lib/python3.7/site-packages/flask/app.py", line 1822, in full_dispatch_request
    rv = self.handle_user_exception(e)
  File "/home/pi/Desktop/math_website/venv/lib/python3.7/site-packages/flask/app.py", line 1820, in full_dispatch_request
    rv = self.dispatch_request()
  File "/home/pi/Desktop/math_website/venv/lib/python3.7/site-packages/flask/app.py", line 1796, in dispatch_request
    return self.ensure_sync(self.view_functions[rule.endpoint])(**view_args)
  File "/home/pi/Desktop/math_website/app/auth/routes.py", line 190, in reset_password_request
    send_password_reset_email(user)
  File "/home/pi/Desktop/math_website/app/auth/email.py", line 20, in send_password_reset_email
    user=user, token=token)
  File "/home/pi/Desktop/math_website/app/email.py", line 33, in send_email
    msg.body = text_body
NameError: name 'msg' is not defined
2023-04-29 09:13:32,493 INFO: Math Website startup [in /home/pi/Desktop/math_website/app/__init__.py:94]
2023-05-02 08:07:43,297 INFO: Math Website startup [in /home/pi/Desktop/math_website/app/__init__.py:94]
2023-05-02 08:08:04,011 INFO: Math Website startup [in /home/pi/Desktop/math_website/app/__init__.py:94]
2023-05-02 08:10:09,226 INFO: Math Website startup [in /home/pi/Desktop/math_website/app/__init__.py:94]
