2023-04-16 09:54:26,551 ERROR: Exception on / [GET] [in /home/pi/Desktop/math_website/venv/lib/python3.7/site-packages/flask/app.py:1742]
Traceback (most recent call last):
  File "/home/pi/Desktop/math_website/venv/lib/python3.7/site-packages/flask/app.py", line 2525, in wsgi_app
    response = self.full_dispatch_request()
  File "/home/pi/Desktop/math_website/venv/lib/python3.7/site-packages/flask/app.py", line 1822, in full_dispatch_request
    rv = self.handle_user_exception(e)
  File "/home/pi/Desktop/math_website/venv/lib/python3.7/site-packages/flask/app.py", line 1820, in full_dispatch_request
    rv = self.dispatch_request()
  File "/home/pi/Desktop/math_website/venv/lib/python3.7/site-packages/flask/app.py", line 1796, in dispatch_request
    return self.ensure_sync(self.view_functions[rule.endpoint])(**view_args)
  File "/home/pi/Desktop/math_website/venv/lib/python3.7/site-packages/flask_login/utils.py", line 285, in decorated_view
    return current_app.login_manager.unauthorized()
  File "/home/pi/Desktop/math_website/venv/lib/python3.7/site-packages/flask_login/login_manager.py", line 196, in unauthorized
    redirect_url = make_login_url(login_view, next_url=request.url)
  File "/home/pi/Desktop/math_website/venv/lib/python3.7/site-packages/flask_login/utils.py", line 120, in login_url
    base = expand_login_view(login_view)
  File "/home/pi/Desktop/math_website/venv/lib/python3.7/site-packages/flask_login/utils.py", line 97, in expand_login_view
    return url_for(login_view)
  File "/home/pi/Desktop/math_website/venv/lib/python3.7/site-packages/flask/helpers.py", line 262, in url_for
    **values,
  File "/home/pi/Desktop/math_website/venv/lib/python3.7/site-packages/flask/app.py", line 2031, in url_for
    return self.handle_url_build_error(error, endpoint, values)
  File "/home/pi/Desktop/math_website/venv/lib/python3.7/site-packages/flask/app.py", line 2025, in url_for
    force_external=_external,
  File "/home/pi/Desktop/math_website/venv/lib/python3.7/site-packages/werkzeug/routing/map.py", line 917, in build
    raise BuildError(endpoint, values, method, self)
werkzeug.routing.exceptions.BuildError: Could not build url for endpoint 'login'. Did you mean 'auth.login' instead?
2023-04-16 10:03:21,212 INFO: Math Website startup [in /home/pi/Desktop/math_website/app/__init__.py:85]
2023-04-16 10:03:29,481 ERROR: Exception on / [GET] [in /home/pi/Desktop/math_website/venv/lib/python3.7/site-packages/flask/app.py:1742]
Traceback (most recent call last):
  File "/home/pi/Desktop/math_website/venv/lib/python3.7/site-packages/flask/app.py", line 2525, in wsgi_app
    response = self.full_dispatch_request()
  File "/home/pi/Desktop/math_website/venv/lib/python3.7/site-packages/flask/app.py", line 1822, in full_dispatch_request
    rv = self.handle_user_exception(e)
  File "/home/pi/Desktop/math_website/venv/lib/python3.7/site-packages/flask/app.py", line 1820, in full_dispatch_request
    rv = self.dispatch_request()
  File "/home/pi/Desktop/math_website/venv/lib/python3.7/site-packages/flask/app.py", line 1796, in dispatch_request
    return self.ensure_sync(self.view_functions[rule.endpoint])(**view_args)
  File "/home/pi/Desktop/math_website/venv/lib/python3.7/site-packages/flask_login/utils.py", line 285, in decorated_view
    return current_app.login_manager.unauthorized()
  File "/home/pi/Desktop/math_website/venv/lib/python3.7/site-packages/flask_login/login_manager.py", line 196, in unauthorized
    redirect_url = make_login_url(login_view, next_url=request.url)
  File "/home/pi/Desktop/math_website/venv/lib/python3.7/site-packages/flask_login/utils.py", line 120, in login_url
    base = expand_login_view(login_view)
  File "/home/pi/Desktop/math_website/venv/lib/python3.7/site-packages/flask_login/utils.py", line 97, in expand_login_view
    return url_for(login_view)
  File "/home/pi/Desktop/math_website/venv/lib/python3.7/site-packages/flask/helpers.py", line 262, in url_for
    **values,
  File "/home/pi/Desktop/math_website/venv/lib/python3.7/site-packages/flask/app.py", line 2031, in url_for
    return self.handle_url_build_error(error, endpoint, values)
  File "/home/pi/Desktop/math_website/venv/lib/python3.7/site-packages/flask/app.py", line 2025, in url_for
    force_external=_external,
  File "/home/pi/Desktop/math_website/venv/lib/python3.7/site-packages/werkzeug/routing/map.py", line 917, in build
    raise BuildError(endpoint, values, method, self)
werkzeug.routing.exceptions.BuildError: Could not build url for endpoint 'login'. Did you mean 'auth.login' instead?
2023-04-16 10:10:07,852 INFO: Math Website startup [in /home/pi/Desktop/math_website/app/__init__.py:85]
2023-04-16 10:10:15,736 ERROR: Exception on / [GET] [in /home/pi/Desktop/math_website/venv/lib/python3.7/site-packages/flask/app.py:1742]
Traceback (most recent call last):
  File "/home/pi/Desktop/math_website/venv/lib/python3.7/site-packages/flask/app.py", line 2525, in wsgi_app
    response = self.full_dispatch_request()
  File "/home/pi/Desktop/math_website/venv/lib/python3.7/site-packages/flask/app.py", line 1822, in full_dispatch_request
    rv = self.handle_user_exception(e)
  File "/home/pi/Desktop/math_website/venv/lib/python3.7/site-packages/flask/app.py", line 1820, in full_dispatch_request
    rv = self.dispatch_request()
  File "/home/pi/Desktop/math_website/venv/lib/python3.7/site-packages/flask/app.py", line 1796, in dispatch_request
    return self.ensure_sync(self.view_functions[rule.endpoint])(**view_args)
  File "/home/pi/Desktop/math_website/venv/lib/python3.7/site-packages/flask_login/utils.py", line 285, in decorated_view
    return current_app.login_manager.unauthorized()
  File "/home/pi/Desktop/math_website/venv/lib/python3.7/site-packages/flask_login/login_manager.py", line 196, in unauthorized
    redirect_url = make_login_url(login_view, next_url=request.url)
  File "/home/pi/Desktop/math_website/venv/lib/python3.7/site-packages/flask_login/utils.py", line 120, in login_url
    base = expand_login_view(login_view)
  File "/home/pi/Desktop/math_website/venv/lib/python3.7/site-packages/flask_login/utils.py", line 97, in expand_login_view
    return url_for(login_view)
  File "/home/pi/Desktop/math_website/venv/lib/python3.7/site-packages/flask/helpers.py", line 262, in url_for
    **values,
  File "/home/pi/Desktop/math_website/venv/lib/python3.7/site-packages/flask/app.py", line 2031, in url_for
    return self.handle_url_build_error(error, endpoint, values)
  File "/home/pi/Desktop/math_website/venv/lib/python3.7/site-packages/flask/app.py", line 2025, in url_for
    force_external=_external,
  File "/home/pi/Desktop/math_website/venv/lib/python3.7/site-packages/werkzeug/routing/map.py", line 917, in build
    raise BuildError(endpoint, values, method, self)
werkzeug.routing.exceptions.BuildError: Could not build url for endpoint 'login'. Did you mean 'auth.login' instead?
2023-04-16 10:15:53,978 INFO: Math Website startup [in /home/pi/Desktop/math_website/app/__init__.py:85]
2023-04-16 10:16:02,371 ERROR: Exception on / [GET] [in /home/pi/Desktop/math_website/venv/lib/python3.7/site-packages/flask/app.py:1742]
Traceback (most recent call last):
  File "/home/pi/Desktop/math_website/venv/lib/python3.7/site-packages/flask/app.py", line 2525, in wsgi_app
    response = self.full_dispatch_request()
  File "/home/pi/Desktop/math_website/venv/lib/python3.7/site-packages/flask/app.py", line 1822, in full_dispatch_request
    rv = self.handle_user_exception(e)
  File "/home/pi/Desktop/math_website/venv/lib/python3.7/site-packages/flask/app.py", line 1820, in full_dispatch_request
    rv = self.dispatch_request()
  File "/home/pi/Desktop/math_website/venv/lib/python3.7/site-packages/flask/app.py", line 1796, in dispatch_request
    return self.ensure_sync(self.view_functions[rule.endpoint])(**view_args)
  File "/home/pi/Desktop/math_website/venv/lib/python3.7/site-packages/flask_login/utils.py", line 285, in decorated_view
    return current_app.login_manager.unauthorized()
  File "/home/pi/Desktop/math_website/venv/lib/python3.7/site-packages/flask_login/login_manager.py", line 196, in unauthorized
    redirect_url = make_login_url(login_view, next_url=request.url)
  File "/home/pi/Desktop/math_website/venv/lib/python3.7/site-packages/flask_login/utils.py", line 120, in login_url
    base = expand_login_view(login_view)
  File "/home/pi/Desktop/math_website/venv/lib/python3.7/site-packages/flask_login/utils.py", line 97, in expand_login_view
    return url_for(login_view)
  File "/home/pi/Desktop/math_website/venv/lib/python3.7/site-packages/flask/helpers.py", line 262, in url_for
    **values,
  File "/home/pi/Desktop/math_website/venv/lib/python3.7/site-packages/flask/app.py", line 2031, in url_for
    return self.handle_url_build_error(error, endpoint, values)
  File "/home/pi/Desktop/math_website/venv/lib/python3.7/site-packages/flask/app.py", line 2025, in url_for
    force_external=_external,
  File "/home/pi/Desktop/math_website/venv/lib/python3.7/site-packages/werkzeug/routing/map.py", line 917, in build
    raise BuildError(endpoint, values, method, self)
werkzeug.routing.exceptions.BuildError: Could not build url for endpoint 'login'. Did you mean 'auth.login' instead?
